<?xml version="1.0" encoding="UTF-8"?>
<!-- Generated by org.testng.reporters.JUnitXMLReporter -->
<testsuite ignored="8" hostname="Lenovo-Ideapad" failures="1" tests="1" name="Default test" time="0.074" errors="0" timestamp="2025-06-12T23:16:03 IST">
  <testcase classname="api.test.UserTest" name="testSignUpUser" time="0.035">
    <failure type="java.lang.AssertionError" message="expected [200] but found [400]">
      <![CDATA[java.lang.AssertionError: expected [200] but found [400]
at org.testng.Assert.fail(Assert.java:111)
at org.testng.Assert.failNotEquals(Assert.java:1590)
at org.testng.Assert.assertEqualsImpl(Assert.java:150)
at org.testng.Assert.assertEquals(Assert.java:132)
at org.testng.Assert.assertEquals(Assert.java:1431)
at org.testng.Assert.assertEquals(Assert.java:1395)
at org.testng.Assert.assertEquals(Assert.java:1441)
at api.test.UserTest.testSignUpUser(UserTest.java:22)
at java.base/jdk.internal.reflect.DirectMethodHandleAccessor.invoke(DirectMethodHandleAccessor.java:104)
at java.base/java.lang.reflect.Method.invoke(Method.java:565)
at org.testng.internal.invokers.MethodInvocationHelper.invokeMethod(MethodInvocationHelper.java:141)
at org.testng.internal.invokers.TestInvoker.invokeMethod(TestInvoker.java:687)
at org.testng.internal.invokers.TestInvoker.invokeTestMethod(TestInvoker.java:230)
at org.testng.internal.invokers.MethodRunner.runInSequence(MethodRunner.java:63)
at org.testng.internal.invokers.TestInvoker$MethodInvocationAgent.invoke(TestInvoker.java:995)
at org.testng.internal.invokers.TestInvoker.invokeTestMethods(TestInvoker.java:203)
at org.testng.internal.invokers.TestMethodWorker.invokeTestMethods(TestMethodWorker.java:154)
at org.testng.internal.invokers.TestMethodWorker.run(TestMethodWorker.java:134)
at java.base/java.util.ArrayList.forEach(ArrayList.java:1604)
at org.testng.TestRunner.privateRun(TestRunner.java:741)
at org.testng.TestRunner.run(TestRunner.java:616)
at org.testng.SuiteRunner.runTest(SuiteRunner.java:421)
at org.testng.SuiteRunner.runSequentially(SuiteRunner.java:413)
at org.testng.SuiteRunner.privateRun(SuiteRunner.java:373)
at org.testng.SuiteRunner.run(SuiteRunner.java:312)
at org.testng.SuiteRunnerWorker.runSuite(SuiteRunnerWorker.java:52)
at org.testng.SuiteRunnerWorker.run(SuiteRunnerWorker.java:95)
at org.testng.TestNG.runSuitesSequentially(TestNG.java:1274)
at org.testng.TestNG.runSuitesLocally(TestNG.java:1208)
at org.testng.TestNG.runSuites(TestNG.java:1112)
at org.testng.TestNG.run(TestNG.java:1079)
at org.testng.remote.AbstractRemoteTestNG.run(AbstractRemoteTestNG.java:115)
at org.testng.remote.RemoteTestNG.initAndRun(RemoteTestNG.java:293)
at org.testng.remote.RemoteTestNG.main(RemoteTestNG.java:91)
]]>
    </failure>
  </testcase> <!-- testSignUpUser -->
  <testcase classname="api.test.UserTest" name="testSignUpWithRawPayloadBody" time="0.0">
    <ignored/>
  </testcase> <!-- testSignUpWithRawPayloadBody -->
  <testcase classname="api.test.UserTest" name="testLoginWithWrongEmail" time="0.0">
    <ignored/>
  </testcase> <!-- testLoginWithWrongEmail -->
  <testcase classname="api.test.UserTest" name="testSignUpWithNoPayloadBody" time="0.0">
    <ignored/>
  </testcase> <!-- testSignUpWithNoPayloadBody -->
  <testcase classname="api.test.UserTest" name="testLoginWithWrongPassword" time="0.0">
    <ignored/>
  </testcase> <!-- testLoginWithWrongPassword -->
  <testcase classname="api.test.UserTest" name="testDuplicateSignUp" time="0.0">
    <ignored/>
  </testcase> <!-- testDuplicateSignUp -->
  <testcase classname="api.test.UserTest" name="testLoginWithNoPayload" time="0.0">
    <ignored/>
  </testcase> <!-- testLoginWithNoPayload -->
  <testcase classname="api.test.UserTest" name="testLoginWithValidCredentials" time="0.0">
    <ignored/>
  </testcase> <!-- testLoginWithValidCredentials -->
  <testcase classname="api.test.UserTest" name="testSignInWithRawPayloadBody" time="0.0">
    <ignored/>
  </testcase> <!-- testSignInWithRawPayloadBody -->
</testsuite> <!-- Default test -->
